Workbook

Sheet Summary_Metrics
A1: Experiment Summary: Control vs Treatment
A2: Source: Clean_Data sheet (deduplicated, 1,400 users). Formulas reference Clean_Data directly.
A4: Metric | B4: Control | C4: Treatment | D4: Absolute Difference | E4: Relative Lift (%)
A5: User count | B5: =COUNTIF(Clean_Data!$C$2:$C$1401,"Control") -> 690 | C5: =COUNTIF(Clean_Data!$C$2:$C$1401,"Treatment") -> 710 | D5: =C5-B5 -> 20 | E5: =IF(B5=0,"N/A",(C5-B5)/B5) -> 0.028985507
A6: Landing page visit rate | B6: =AVERAGEIFS(Clean_Data!$H$2:$H$1401,Clean_Data!$C$2:$C$1401,"Control") -> 0.63623188 | C6: =AVERAGEIFS(Clean_Data!$H$2:$H$1401,Clean_Data!$C$2:$C$1401,"Treatment") -> 0.72394366 | D6: =C6-B6 -> 0.087711778 | E6: =IF(B6=0,"N/A",(C6-B6)/B6) -> 0.13786134
A7: Trial start rate | B7: =AVERAGEIFS(Clean_Data!$I$2:$I$1401,Clean_Data!$C$2:$C$1401,"Control") -> 0.25072464 | C7: =AVERAGEIFS(Clean_Data!$I$2:$I$1401,Clean_Data!$C$2:$C$1401,"Treatment") -> 0.29014085 | D7: =C7-B7 -> 0.039416207 | E7: =IF(B7=0,"N/A",(C7-B7)/B7) -> 0.15720915
A8: Onboarding completion rate | B8: =AVERAGEIFS(Clean_Data!$J$2:$J$1401,Clean_Data!$C$2:$C$1401,"Control") -> 0.15652174 | C8: =AVERAGEIFS(Clean_Data!$J$2:$J$1401,Clean_Data!$C$2:$C$1401,"Treatment") -> 0.21126761 | D8: =C8-B8 -> 0.054745867 | E8: =IF(B8=0,"N/A",(C8-B8)/B8) -> 0.34976526
A9: Paid conversion rate | B9: =AVERAGEIFS(Clean_Data!$K$2:$K$1401,Clean_Data!$C$2:$C$1401,"Control") -> 0.031884058 | C9: =AVERAGEIFS(Clean_Data!$K$2:$K$1401,Clean_Data!$C$2:$C$1401,"Treatment") -> 0.070422535 | D9: =C9-B9 -> 0.038538477 | E9: =IF(B9=0,"N/A",(C9-B9)/B9) -> 1.2087068
A10: Average revenue per user (ARPU) | B10: =AVERAGEIFS(Clean_Data!$L$2:$L$1401,Clean_Data!$C$2:$C$1401,"Control") -> 51.974319 | C10: =AVERAGEIFS(Clean_Data!$L$2:$L$1401,Clean_Data!$C$2:$C$1401,"Treatment") -> 54.254521 | D10: =C10-B10 -> 2.2802023 | E10: =IF(B10=0,"N/A",(C10-B10)/B10) -> 0.043871711
A11: Average revenue per converted user | B11: =SUMIFS(Clean_Data!$L$2:$L$1401,Clean_Data!$C$2:$C$1401,"Control",Clean_Data!$K$2:$K$1401,1)/COUNTIFS(Clean_Data!$C$2:$C$1401,"Control",Clean_Data!$K$2:$K$1401,1) -> 1630.1036 | C11: =SUMIFS(Clean_Data!$L$2:$L$1401,Clean_Data!$C$2:$C$1401,"Treatment",Clean_Data!$K$2:$K$1401,1)/COUNTIFS(Clean_Data!$C$2:$C$1401,"Treatment",Clean_Data!$K$2:$K$1401,1) -> 770.4142 | D11: =C11-B11 -> -859.68944 | E11: =IF(B11=0,"N/A",(C11-B11)/B11) -> -0.5273833
A12: Refund rate | B12: =AVERAGEIFS(Clean_Data!$N$2:$N$1401,Clean_Data!$C$2:$C$1401,"Control") -> 0 | C12: =AVERAGEIFS(Clean_Data!$N$2:$N$1401,Clean_Data!$C$2:$C$1401,"Treatment") -> 0.0042253521 | D12: =C12-B12 -> 0.0042253521 | E12: =IF(B12=0,"N/A",(C12-B12)/B12) -> N/A
A13: Support ticket rate (users with >=1 ticket) | B13: =COUNTIFS(Clean_Data!$C$2:$C$1401,"Control",Clean_Data!$M$2:$M$1401,">0")/COUNTIF(Clean_Data!$C$2:$C$1401,"Control") -> 0.14782609 | C13: =COUNTIFS(Clean_Data!$C$2:$C$1401,"Treatment",Clean_Data!$M$2:$M$1401,">0")/COUNTIF(Clean_Data!$C$2:$C$1401,"Treatment") -> 0.24788732 | D13: =C13-B13 -> 0.10006124 | E13: =IF(B13=0,"N/A",(C13-B13)/B13) -> 0.67688484
A14: Average engagement score | B14: =AVERAGEIFS(Clean_Data!$P$2:$P$1401,Clean_Data!$C$2:$C$1401,"Control") -> 57.029532 | C14: =AVERAGEIFS(Clean_Data!$P$2:$P$1401,Clean_Data!$C$2:$C$1401,"Treatment") -> 62.940028 | D14: =C14-B14 -> 5.9104963 | E14: =IF(B14=0,"N/A",(C14-B14)/B14) -> 0.10363922
A15: Average days to convert (converters only) | B15: =AVERAGEIFS(Clean_Data!$O$2:$O$1401,Clean_Data!$C$2:$C$1401,"Control",Clean_Data!$K$2:$K$1401,1) -> 8.8636364 | C15: =AVERAGEIFS(Clean_Data!$O$2:$O$1401,Clean_Data!$C$2:$C$1401,"Treatment",Clean_Data!$K$2:$K$1401,1) -> 6.4 | D15: =C15-B15 -> -2.4636364 | E15: =IF(B15=0,"N/A",(C15-B15)/B15) -> -0.27794872

Sheet Clean_Data
A1: user_id | B1: signup_date | C1: experiment_group | D1: region | E1: device_type | F1: traffic_source | G1: plan_type | H1: visited_landing_page | I1: started_trial | J1: completed_onboarding | K1: converted_to_paid | L1: revenue_30d | M1: support_tickets_30d | N1: refund_requested | O1: days_to_convert | P1: engagement_score
A2: USR-100001 | B2: 2025-03-16 | C2: Control | D2: North | E2: Desktop | F2: Email | G2: Basic | H2: 0 | I2: 0 | J2: 0 | K2: 0 | L2: 0 | M2: 0 | N2: 0 | P2: 45.7
A3: USR-100002 | B3: 2025-03-08 | C3: Control | D3: West | E3: Mobile | F3: Organic | G3: Free | H3: 1 | I3: 0 | J3: 0 | K3: 0 | L3: 0 | M3: 0 | N3: 0 | P3: 48.6
A4: USR-100003 | B4: 2025-04-24 | C4: Control | D4: East | E4: Mobile | F4: Paid Search | G4: Premium | H4: 1 | I4: 0 | J4: 0 | K4: 0 | L4: 0 | M4: 1 | N4: 0 | P4: 35.4
A5: USR-100004 | B5: 2025-05-04 | C5: Control | D5: South | E5: Mobile | F5: Email | G5: Basic | H5: 1 | I5: 0 | J5: 0 | K5: 0 | L5: 0 | M5: 0 | N5: 0 | P5: 64.6
A6: USR-100005 | B6: 2025-02-12 | C6: Control | D6: North | E6: Tablet | F6: Organic | G6: Free | H6: 0 | I6: 0 | J6: 0 | K6: 0 | L6: 0 | M6: 0 | N6: 0 | P6: 66.6
A7: USR-100006 | B7: 2025-01-28 | C7: Control | D7: East | E7: Mobile | F7: Organic | G7: Premium | H7: 1 | I7: 0 | J7: 0 | K7: 0 | L7: 0 | M7: 0 | N7: 0 | P7: 40.8
A8: USR-100007 | B8: 2025-04-08 | C8: Control | D8: East | E8: Mobile | F8: Paid Search | G8: Basic | H8: 1 | I8: 1 | J8: 0 | K8: 0 | L8: 0 | M8: 0 | N8: 0 | P8: 57.1
A9: USR-100008 | B9: 2025-05-17 | C9: Control | D9: South | E9: Mobile | F9: Paid Search | G9: Free | H9: 0 | I9: 0 | J9: 0 | K9: 0 | L9: 0 | M9: 0 | N9: 0 | P9: 36.4
A10: USR-100009 | B10: 2025-02-23 | C10: Control | D10: South | E10: Tablet | F10: Referral | G10: Basic | H10: 0 | I10: 0 | J10: 0 | K10: 0 | L10: 0 | M10: 0 | N10: 0 | P10: 55.4
A11: USR-100010 | B11: 2025-05-29 | C11: Control | D11: West | E11: Desktop | F11: Social | G11: Free | H11: 1 | I11: 0 | J11: 0 | K11: 0 | L11: 0 | M11: 0 | N11: 0 | P11: 57.3
A12: USR-100011 | B12: 2025-04-30 | C12: Control | D12: East | E12: Mobile | F12: Paid Search | G12: Basic | H12: 1 | I12: 1 | J12: 1 | K12: 0 | L12: 0 | M12: 0 | N12: 0 | P12: 63.6
A13: USR-100012 | B13: 2025-03-16 | C13: Control | D13: East | E13: Mobile | F13: Social | G13: Premium | H13: 1 | I13: 1 | J13: 1 | K13: 0 | L13: 0 | M13: 1 | N13: 0 | P13: 80.4
... A60: USR-100059 | B60: 2025-04-14 | C60: Control | D60: North | E60: Mobile | F60: Social | G60: Free | H60: 0 | I60: 0 | J60: 0 | K60: 0 | L60: 0 | M60: 2 | N60: 0 | P60: 48.9
A61: USR-100060 | B61: 2025-01-01 | C61: Control | D61: West | E61: Mobile | F61: Social | G61: Free | H61: 1 | I61: 1 | J61: 1 | K61: 1 | L61: 240.42 | M61: 0 | N61: 0 | O61: 16 | P61: 56.5
A62: USR-100061 | B62: 2025-04-02 | C62: Control | D62: South | E62: Mobile | F62: Referral | G62: Free | H62: 1 | I62: 0 | J62: 0 | K62: 0 | L62: 0 | M62: 0 | N62: 0 | P62: 53.7
A63: USR-100062 | B63: 2025-03-29 | C63: Control | D63: North | E63: Mobile | F63: Social | G63: Premium | H63: 0 | I63: 0 | J63: 0 | K63: 0 | L63: 0 | M63: 0 | N63: 0 | P63: 62.2
A64: USR-100063 | B64: 2025-05-15 | C64: Control | D64: South | E64: Desktop | F64: Organic | G64: Free | H64: 1 | I64: 0 | J64: 0 | K64: 0 | L64: 0 | M64: 0 | N64: 0 | P64: 50.2
A65: USR-100064 | B65: 2025-04-11 | C65: Control | D65: North | E65: Mobile | F65: Organic | G65: Basic | H65: 1 | I65: 0 | J65: 0 | K65: 0 | L65: 0 | M65: 0 | N65: 0 | P65: 74.3
A66: USR-100065 | B66: 2025-03-07 | C66: Control | D66: South | E66: Desktop | F66: Paid Search | G66: Free | H66: 1 | I66: 0 | J66: 0 | K66: 0 | L66: 0 | M66: 0 | N66: 0 | P66: 58
A67: USR-100066 | B67: 2025-05-30 | C67: Control | D67: South | E67: Mobile | F67: Organic | G67: Free | H67: 0 | I67: 0 | J67: 0 | K67: 0 | L67: 0 | M67: 0 | N67: 0 | P67: 46.7
A68: USR-100067 | B68: 2025-01-07 | C68: Control | D68: South | E68: Desktop | F68: Organic | G68: Premium | H68: 1 | I68: 0 | J68: 0 | K68: 0 | L68: 0 | M68: 1 | N68: 0 | P68: 49.6
A69: USR-100068 | B69: 2025-05-08 | C69: Control | D69: West | E69: Mobile | F69: Social | G69: Free | H69: 0 | I69: 0 | J69: 0 | K69: 0 | L69: 0 | M69: 0 | N69: 0 | P69: 60.4
A70: USR-100069 | B70: 2025-03-19 | C70: Control | D70: East | E70: Desktop | F70: Email | G70: Free | H70: 1 | I70: 1 | J70: 1 | K70: 0 | L70: 0 | M70: 0 | N70: 0 | P70: 55.3
A71: USR-100070 | B71: 2025-05-16 | C71: Control | D71: North | E71: Desktop | F71: Organic | G71: Free | H71: 0 | I71: 0 | J71: 0 | K71: 0 | L71: 0 | M71: 0 | N71: 0 | P71: 56.2
A72: USR-100071 | B72: 2025-03-08 | C72: Control | D72: West | E72: Mobile | F72: Email | G72: Free | H72: 0 | I72: 0 | J72: 0 | K72: 0 | L72: 0 | M72: 0 | N72: 0 | P72: 29.4
A73: USR-100072 | B73: 2025-03-08 | C73: Control | D73: East | E73: Mobile | F73: Email | G73: Free | H73: 1 | I73: 0 | J73: 0 | K73: 0 | L73: 0 | M73: 0 | N73: 0 | P73: 54.2
... A79: USR-100078 | B79: 2025-01-16 | C79: Control | D79: North | E79: Mobile | F79: Organic | G79: Free | H79: 0 | I79: 0 | J79: 0 | K79: 0 | L79: 0 | M79: 2 | N79: 0 | P79: 48.4
A80: USR-100079 | B80: 2025-02-20 | C80: Control | D80: West | E80: Desktop | F80: Organic | G80: Free | H80: 1 | I80: 1 | J80: 1 | K80: 1 | L80: 457.51 | M80: 0 | N80: 0 | O80: 7 | P80: 38
A81: USR-100080 | B81: 2025-05-21 | C81: Control | D81: East | E81: Mobile | F81: Social | G81: Free | H81: 1 | I81: 0 | J81: 0 | K81: 0 | L81: 0 | M81: 0 | N81: 0 | P81: 44.2
A82: USR-100081 | B82: 2025-05-08 | C82: Control | D82: South | E82: Mobile | F82: Organic | G82: Free | H82: 1 | I82: 1 | J82: 1 | K82: 0 | L82: 0 | M82: 0 | N82: 0 | P82: 81.2
A83: USR-100082 | B83: 2025-03-08 | C83: Control | D83: South | E83: Mobile | F83: Referral | G83: Free | H83: 1 | I83: 1 | J83: 0 | K83: 0 | L83: 0 | M83: 0 | N83: 0 | P83: 63.8
A84: USR-100083 | B84: 2025-04-01 | C84: Control | D84: South | E84: Desktop | F84: Email | G84: Free | H84: 0 | I84: 0 | J84: 0 | K84: 0 | L84: 0 | M84: 0 | N84: 0 | P84: 64.7
A85: USR-100084 | B85: 2025-03-03 | C85: Control | D85: West | E85: Mobile | F85: Social | G85: Basic | H85: 0 | I85: 0 | J85: 0 | K85: 0 | L85: 0 | M85: 0 | N85: 0 | P85: 60.4
A86: USR-100085 | B86: 2025-04-16 | C86: Control | D86: South | E86: Mobile | F86: Paid Search | G86: Free | H86: 0 | I86: 0 | J86: 0 | K86: 0 | L86: 0 | M86: 0 | N86: 0 | P86: 66.6
A87: USR-100086 | B87: 2025-01-09 | C87: Control | D87: North | E87: Desktop | F87: Organic | G87: Free | H87: 1 | I87: 0 | J87: 0 | K87: 0 | L87: 0 | M87: 0 | N87: 0 | P87: 50.9
A88: USR-100087 | B88: 2025-01-22 | C88: Control | D88: West | E88: Desktop | F88: Social | G88: Basic | H88: 0 | I88: 0 | J88: 0 | K88: 0 | L88: 0 | M88: 0 | N88: 0 | P88: 51
A89: USR-100088 | B89: 2025-04-30 | C89: Control | D89: South | E89: Mobile | F89: Email | G89: Premium | H89: 0 | I89: 0 | J89: 0 | K89: 0 | L89: 0 | M89: 0 | N89: 0 | P89: 65.8
A90: USR-100089 | B90: 2025-04-25 | C90: Control | D90: North | E90: Mobile | F90: Referral | G90: Basic | H90: 1 | I90: 0 | J90: 0 | K90: 0 | L90: 0 | M90: 0 | N90: 0 | P90: 61.8
A91: USR-100090 | B91: 2025-02-01 | C91: Control | D91: North | E91: Mobile | F91: Organic | G91: Basic | H91: 1 | I91: 0 | J91: 0 | K91: 0 | L91: 0 | M91: 0 | N91: 0 | P91: 54.5
...

Sheet Segment_Breakdown
A1: Paid Conversion Rate by Segment: Control vs Treatment
A2: At least 3 metrics analyzed by segment, per assignment requirement. Shown here: Paid conversion rate, Onboarding completion rate, and Average engagement score, each cut by Region, Device Type, and Plan Type.
A4: Paid conversion rate
A5: Region | B5: Control | C5: Treatment | D5: Difference
A6: East | B6: =AVERAGEIFS(Clean_Data!$K$2:$K$1401,Clean_Data!$C$2:$C$1401,"Control",Clean_Data!$D$2:$D$1401,"East") -> 0.025477707 | C6: =AVERAGEIFS(Clean_Data!$K$2:$K$1401,Clean_Data!$C$2:$C$1401,"Treatment",Clean_Data!$D$2:$D$1401,"East") -> 0.064705882 | D6: =C6-B6 -> 0.039228175
A7: North | B7: =AVERAGEIFS(Clean_Data!$K$2:$K$1401,Clean_Data!$C$2:$C$1401,"Control",Clean_Data!$D$2:$D$1401,"North") -> 0.034825871 | C7: =AVERAGEIFS(Clean_Data!$K$2:$K$1401,Clean_Data!$C$2:$C$1401,"Treatment",Clean_Data!$D$2:$D$1401,"North") -> 0.088888889 | D7: =C7-B7 -> 0.054063018
A8: South | B8: =AVERAGEIFS(Clean_Data!$K$2:$K$1401,Clean_Data!$C$2:$C$1401,"Control",Clean_Data!$D$2:$D$1401,"South") -> 0.032608696 | C8: =AVERAGEIFS(Clean_Data!$K$2:$K$1401,Clean_Data!$C$2:$C$1401,"Treatment",Clean_Data!$D$2:$D$1401,"South") -> 0.076502732 | D8: =C8-B8 -> 0.043894037
A9: West | B9: =AVERAGEIFS(Clean_Data!$K$2:$K$1401,Clean_Data!$C$2:$C$1401,"Control",Clean_Data!$D$2:$D$1401,"West") -> 0.033783784 | C9: =AVERAGEIFS(Clean_Data!$K$2:$K$1401,Clean_Data!$C$2:$C$1401,"Treatment",Clean_Data!$D$2:$D$1401,"West") -> 0.050847458 | D9: =C9-B9 -> 0.017063674
A10: Device Type | B10: Control | C10: Treatment | D10: Difference
A12: Desktop | B12: =AVERAGEIFS(Clean_Data!$K$2:$K$1401,Clean_Data!$C$2:$C$1401,"Control",Clean_Data!$E$2:$E$1401,"Desktop") -> 0.045 | C12: =AVERAGEIFS(Clean_Data!$K$2:$K$1401,Clean_Data!$C$2:$C$1401,"Treatment",Clean_Data!$E$2:$E$1401,"Desktop") -> 0.0657277 | D12: =C12-B12 -> 0.0207277
A13: Mobile | B13: =AVERAGEIFS(Clean_Data!$K$2:$K$1401,Clean_Data!$C$2:$C$1401,"Control",Clean_Data!$E$2:$E$1401,"Mobile") -> 0.025821596 | C13: =AVERAGEIFS(Clean_Data!$K$2:$K$1401,Clean_Data!$C$2:$C$1401,"Treatment",Clean_Data!$E$2:$E$1401,"Mobile") -> 0.074074074 | D13: =C13-B13 -> 0.048252478
A14: Tablet | B14: =AVERAGEIFS(Clean_Data!$K$2:$K$1401,Clean_Data!$C$2:$C$1401,"Control",Clean_Data!$E$2:$E$1401,"Tablet") -> 0.018181818 | C14: =AVERAGEIFS(Clean_Data!$K$2:$K$1401,Clean_Data!$C$2:$C$1401,"Treatment",Clean_Data!$E$2:$E$1401,"Tablet") -> 0.071428571 | D14: =C14-B14 -> 0.053246753
A15: Plan Type | B15: Control | C15: Treatment | D15: Difference
A17: Basic | B17: =AVERAGEIFS(Clean_Data!$K$2:$K$1401,Clean_Data!$C$2:$C$1401,"Control",Clean_Data!$G$2:$G$1401,"Basic") -> 0.036199095 | C17: =AVERAGEIFS(Clean_Data!$K$2:$K$1401,Clean_Data!$C$2:$C$1401,"Treatment",Clean_Data!$G$2:$G$1401,"Basic") -> 0.038793103 | D17: =C17-B17 -> 0.0025940084
A18: Free | B18: =AVERAGEIFS(Clean_Data!$K$2:$K$1401,Clean_Data!$C$2:$C$1401,"Control",Clean_Data!$G$2:$G$1401,"Free") -> 0.030555556 | C18: =AVERAGEIFS(Clean_Data!$K$2:$K$1401,Clean_Data!$C$2:$C$1401,"Treatment",Clean_Data!$G$2:$G$1401,"Free") -> 0.092896175 | D18: =C18-B18 -> 0.062340619
A19: Premium | B19: =AVERAGEIFS(Clean_Data!$K$2:$K$1401,Clean_Data!$C$2:$C$1401,"Control",Clean_Data!$G$2:$G$1401,"Premium") -> 0.027522936 | C19: =AVERAGEIFS(Clean_Data!$K$2:$K$1401,Clean_Data!$C$2:$C$1401,"Treatment",Clean_Data!$G$2:$G$1401,"Premium") -> 0.0625 | D19: =C19-B19 -> 0.034977064
A22: Onboarding completion rate
A23: Region | B23: Control | C23: Treatment | D23: Difference
A24: East | B24: =AVERAGEIFS(Clean_Data!$J$2:$J$1401,Clean_Data!$C$2:$C$1401,"Control",Clean_Data!$D$2:$D$1401,"East") -> 0.20382166 | C24: =AVERAGEIFS(Clean_Data!$J$2:$J$1401,Clean_Data!$C$2:$C$1401,"Treatment",Clean_Data!$D$2:$D$1401,"East") -> 0.21176471 | D24: =C24-B24 -> 0.0079430498
A25: North | B25: =AVERAGEIFS(Clean_Data!$J$2:$J$1401,Clean_Data!$C$2:$C$1401,"Control",Clean_Data!$D$2:$D$1401,"North") -> 0.13930348 | C25: =AVERAGEIFS(Clean_Data!$J$2:$J$1401,Clean_Data!$C$2:$C$1401,"Treatment",Clean_Data!$D$2:$D$1401,"North") -> 0.23888889 | D25: =C25-B25 -> 0.099585406
A26: South | B26: =AVERAGEIFS(Clean_Data!$J$2:$J$1401,Clean_Data!$C$2:$C$1401,"Control",Clean_Data!$D$2:$D$1401,"South") -> 0.13043478 | C26: =AVERAGEIFS(Clean_Data!$J$2:$J$1401,Clean_Data!$C$2:$C$1401,"Treatment",Clean_Data!$D$2:$D$1401,"South") -> 0.21857923 | D26: =C26-B26 -> 0.088144452
A27: West | B27: =AVERAGEIFS(Clean_Data!$J$2:$J$1401,Clean_Data!$C$2:$C$1401,"Control",Clean_Data!$D$2:$D$1401,"West") -> 0.16216216 | C27: =AVERAGEIFS(Clean_Data!$J$2:$J$1401,Clean_Data!$C$2:$C$1401,"Treatment",Clean_Data!$D$2:$D$1401,"West") -> 0.17514124 | D27: =C27-B27 -> 0.012979081
A28: Device Type | B28: Control | C28: Treatment | D28: Difference
A30: Desktop | B30: =AVERAGEIFS(Clean_Data!$J$2:$J$1401,Clean_Data!$C$2:$C$1401,"Control",Clean_Data!$E$2:$E$1401,"Desktop") -> 0.175 | C30: =AVERAGEIFS(Clean_Data!$J$2:$J$1401,Clean_Data!$C$2:$C$1401,"Treatment",Clean_Data!$E$2:$E$1401,"Desktop") -> 0.18779343 | D30: =C30-B30 -> 0.012793427
A31: Mobile | B31: =AVERAGEIFS(Clean_Data!$J$2:$J$1401,Clean_Data!$C$2:$C$1401,"Control",Clean_Data!$E$2:$E$1401,"Mobile") -> 0.13849765 | C31: =AVERAGEIFS(Clean_Data!$J$2:$J$1401,Clean_Data!$C$2:$C$1401,"Treatment",Clean_Data!$E$2:$E$1401,"Mobile") -> 0.22222222 | D31: =C31-B31 -> 0.08372457
A32: Tablet | B32: =AVERAGEIFS(Clean_Data!$J$2:$J$1401,Clean_Data!$C$2:$C$1401,"Control",Clean_Data!$E$2:$E$1401,"Tablet") -> 0.18181818 | C32: =AVERAGEIFS(Clean_Data!$J$2:$J$1401,Clean_Data!$C$2:$C$1401,"Treatment",Clean_Data!$E$2:$E$1401,"Tablet") -> 0.23214286 | D32: =C32-B32 -> 0.050324675
A33: Plan Type | B33: Control | C33: Treatment | D33: Difference
A35: Basic | B35: =AVERAGEIFS(Clean_Data!$J$2:$J$1401,Clean_Data!$C$2:$C$1401,"Control",Clean_Data!$G$2:$G$1401,"Basic") -> 0.14027149 | C35: =AVERAGEIFS(Clean_Data!$J$2:$J$1401,Clean_Data!$C$2:$C$1401,"Treatment",Clean_Data!$G$2:$G$1401,"Basic") -> 0.18965517 | D35: =C35-B35 -> 0.049383679
A36: Free | B36: =AVERAGEIFS(Clean_Data!$J$2:$J$1401,Clean_Data!$C$2:$C$1401,"Control",Clean_Data!$G$2:$G$1401,"Free") -> 0.15555556 | C36: =AVERAGEIFS(Clean_Data!$J$2:$J$1401,Clean_Data!$C$2:$C$1401,"Treatment",Clean_Data!$G$2:$G$1401,"Free") -> 0.23497268 | D36: =C36-B36 -> 0.079417122
A37: Premium | B37: =AVERAGEIFS(Clean_Data!$J$2:$J$1401,Clean_Data!$C$2:$C$1401,"Control",Clean_Data!$G$2:$G$1401,"Premium") -> 0.19266055 | C37: =AVERAGEIFS(Clean_Data!$J$2:$J$1401,Clean_Data!$C$2:$C$1401,"Treatment",Clean_Data!$G$2:$G$1401,"Premium") -> 0.17857143 | D37: =C37-B37 -> -0.014089122
A40: Average engagement score
A41: Region | B41: Control | C41: Treatment | D41: Difference
A42: East | B42: =AVERAGEIFS(Clean_Data!$P$2:$P$1401,Clean_Data!$C$2:$C$1401,"Control",Clean_Data!$D$2:$D$1401,"East") -> 56.556051 | C42: =AVERAGEIFS(Clean_Data!$P$2:$P$1401,Clean_Data!$C$2:$C$1401,"Treatment",Clean_Data!$D$2:$D$1401,"East") -> 63.307692 | D42: =C42-B42 -> 6.7516414
A43: North | B43: =AVERAGEIFS(Clean_Data!$P$2:$P$1401,Clean_Data!$C$2:$C$1401,"Control",Clean_Data!$D$2:$D$1401,"North") -> 57.616667 | C43: =AVERAGEIFS(Clean_Data!$P$2:$P$1401,Clean_Data!$C$2:$C$1401,"Treatment",Clean_Data!$D$2:$D$1401,"North") -> 63.153977 | D43: =C43-B43 -> 5.5373106
A44: South | B44: =AVERAGEIFS(Clean_Data!$P$2:$P$1401,Clean_Data!$C$2:$C$1401,"Control",Clean_Data!$D$2:$D$1401,"South") -> 56.904972 | C44: =AVERAGEIFS(Clean_Data!$P$2:$P$1401,Clean_Data!$C$2:$C$1401,"Treatment",Clean_Data!$D$2:$D$1401,"South") -> 62.11326 | D44: =C44-B44 -> 5.2082873
A45: West | B45: =AVERAGEIFS(Clean_Data!$P$2:$P$1401,Clean_Data!$C$2:$C$1401,"Control",Clean_Data!$D$2:$D$1401,"West") -> 56.898649 | C45: =AVERAGEIFS(Clean_Data!$P$2:$P$1401,Clean_Data!$C$2:$C$1401,"Treatment",Clean_Data!$D$2:$D$1401,"West") -> 63.223295 | D45: =C45-B45 -> 6.3246468
A46: Device Type | B46: Control | C46: Treatment | D46: Difference
A48: Desktop | B48: =AVERAGEIFS(Clean_Data!$P$2:$P$1401,Clean_Data!$C$2:$C$1401,"Control",Clean_Data!$E$2:$E$1401,"Desktop") -> 57.212563 | C48: =AVERAGEIFS(Clean_Data!$P$2:$P$1401,Clean_Data!$C$2:$C$1401,"Treatment",Clean_Data!$E$2:$E$1401,"Desktop") -> 63.210427 | D48: =C48-B48 -> 5.9978637
A49: Mobile | B49: =AVERAGEIFS(Clean_Data!$P$2:$P$1401,Clean_Data!$C$2:$C$1401,"Control",Clean_Data!$E$2:$E$1401,"Mobile") -> 57.363981 | C49: =AVERAGEIFS(Clean_Data!$P$2:$P$1401,Clean_Data!$C$2:$C$1401,"Treatment",Clean_Data!$E$2:$E$1401,"Mobile") -> 62.813615 | D49: =C49-B49 -> 5.449634
A50: Tablet | B50: =AVERAGEIFS(Clean_Data!$P$2:$P$1401,Clean_Data!$C$2:$C$1401,"Control",Clean_Data!$E$2:$E$1401,"Tablet") -> 55.662963 | C50: =AVERAGEIFS(Clean_Data!$P$2:$P$1401,Clean_Data!$C$2:$C$1401,"Treatment",Clean_Data!$E$2:$E$1401,"Tablet") -> 63.007143 | D50: =C50-B50 -> 7.3441799
...
